<?xml version="1.0" encoding="utf-8"?>
<robot  name="rm_eco63" xmlns:xacro="http://www.ros.org/wiki/xacro">
<xacro:include filename="$(find rm_description)/urdf/ECO63/rm_eco63.transmission.xacro"/>
<xacro:include filename="$(find rm_description)/urdf/ECO63/rm_eco63.gazebo.xacro"/>
  <!-- Inertial matrix -->
<xacro:macro name="inertial_matrix" params="mass">
<inertial>
    <mass value="${mass}" />
    <inertia ixx="1.0" ixy="0.0" ixz="0.0" iyy="0.5" iyz="0.0" izz="1.0" />
</inertial>
</xacro:macro>
 <xacro:macro name="Box_inertial_matrix" params="m l w h">
       <inertial>
               <mass value="${m}" />
               <inertia ixx="${m*(h*h + l*l)/12}" ixy = "0" ixz = "0"
                   iyy="${m*(w*w + l*l)/12}" iyz= "0"
                   izz="${m*(w*w + h*h)/12}" />
       </inertial>
  </xacro:macro>

    <link name="dummy">
    </link>
    <joint name="dummy_joint" type="fixed">
      <parent link="dummy" />
      <child link="base_link" />
    </joint>
  
  <!-- ///////////////////////////////////////   bottom_joint   ////////////////////////////////////////// -->
  <joint name="bottom_joint" type="fixed">
    <origin xyz="0 0 0" rpy="0 0 0" />
    <parent link="base_link"/>
    <child link="bottom_link"/>
  </joint>
  <link name="bottom_link">
    <visual>
      <origin xyz=" 0 0 -0.02"  rpy="0 0 0"/>
      <geometry>
        <box size="0.06 0.06 0.02" />
      </geometry>
      <material name="Brown" />
    </visual>
    <collision>
      <origin xyz=" 0 0 -0.02"  rpy="0 0 0"/>
      <geometry>
        <box size="0.06 0.06 0.02" />
      </geometry>
    </collision>
    <xacro:Box_inertial_matrix m="500" l="1" w="1" h="0.02"/>
  </link>


  <link
    name="base_link">
    <inertial>
      <origin
        xyz="0.00039308 -8.9311E-05 0.050351"
        rpy="0 0 0" />
      <mass
        value="0.70684" />
      <inertia
        ixx="0.001114"
        ixy="3.3208E-06"
        ixz="-2.5536E-05"
        iyy="0.0011138"
        iyz="1.4832E-06"
        izz="0.00075793" />
    </inertial>
    <visual>
      <origin
        xyz="0 0 0"
        rpy="0 0 0" />
      <geometry>
        <mesh
          filename="package://rm_description/meshes/ECO63/base_link.STL" />
      </geometry>
      <material
        name="">
        <color
          rgba="0.79216 0.81961 0.93333 1" />
      </material>
    </visual>
    <collision>
      <origin
        xyz="0 0 0"
        rpy="0 0 0" />
      <geometry>
        <mesh
          filename="package://rm_description/meshes/ECO63/base_link.STL" />
      </geometry>
    </collision>
  </link>
  <link
    name="Link1">
    <inertial>
      <origin
        xyz="-0.032161 -0.002588 -0.0071715"
        rpy="0 0 0" />
      <mass
        value="0.7339" />
      <inertia
        ixx="0.00065754"
        ixy="-0.00012029"
        ixz="0.00016575"
        iyy="0.0018838"
        iyz="1.5479E-05"
        izz="0.0017351" />
    </inertial>
    <visual>
      <origin
        xyz="0 0 0"
        rpy="0 0 0" />
      <geometry>
        <mesh
          filename="package://rm_description/meshes/ECO63/Link1.STL" />
      </geometry>
      <material
        name="">
        <color
          rgba="0.79216 0.81961 0.93333 1" />
      </material>
    </visual>
    <collision>
      <origin
        xyz="0 0 0"
        rpy="0 0 0" />
      <geometry>
        <mesh
          filename="package://rm_description/meshes/ECO63/Link1.STL" />
      </geometry>
    </collision>
  </link>
  <joint
    name="joint1"
    type="revolute">
    <origin
      xyz="0 0 0.1625"
      rpy="0 0 0" />
    <parent
      link="base_link" />
    <child
      link="Link1" />
    <axis
      xyz="0 0 1" />
    <limit
      lower="-3.1"
      upper="3.1"
      effort="100"
      velocity="1" />
      <dynamics
      damping="50"
      friction="1" />
  </joint>
  <link
    name="Link2">
    <inertial>
      <origin
        xyz="0.19469 6.6139E-07 -0.070874"
        rpy="0 0 0" />
      <mass
        value="1.9492" />
      <inertia
        ixx="0.001497"
        ixy="1.4887E-07"
        ixz="-0.00045122"
        iyy="0.040644"
        iyz="1.3757E-08"
        izz="0.040997" />
    </inertial>
    <visual>
      <origin
        xyz="0 0 0"
        rpy="0 0 0" />
      <geometry>
        <mesh
          filename="package://rm_description/meshes/ECO63/Link2.STL" />
      </geometry>
      <material
        name="">
        <color
          rgba="0.79216 0.81961 0.93333 1" />
      </material>
    </visual>
    <collision>
      <origin
        xyz="0 0 0"
        rpy="0 0 0" />
      <geometry>
        <mesh
          filename="package://rm_description/meshes/ECO63/Link2.STL" />
      </geometry>
    </collision>
  </link>
  <joint
    name="joint2"
    type="revolute">
    <origin
      xyz="-0.086 0 0"
      rpy="-1.5708 -1.5708 0" />
    <parent
      link="Link1" />
    <child
      link="Link2" />
    <axis
      xyz="0 0 1" />
    <limit
      lower="-3.1"
      upper="3.1"
      effort="100"
      velocity="1" />
      <dynamics
      damping="50"
      friction="1" />
  </joint>
  <link
    name="Link3">
    <inertial>
      <origin
        xyz="0.1718 6.3595E-07 0.026691"
        rpy="0 0 0" />
      <mass
        value="1.4553" />
      <inertia
        ixx="0.00094612"
        ixy="-1.1572E-07"
        ixz="-0.0008623"
        iyy="0.025574"
        iyz="-2.426E-08"
        izz="0.025646" />
    </inertial>
    <visual>
      <origin
        xyz="0 0 0"
        rpy="0 0 0" />
      <geometry>
        <mesh
          filename="package://rm_description/meshes/ECO63/Link3.STL" />
      </geometry>
      <material
        name="">
        <color
          rgba="0.79216 0.81961 0.93333 1" />
      </material>
    </visual>
    <collision>
      <origin
        xyz="0 0 0"
        rpy="0 0 0" />
      <geometry>
        <mesh
          filename="package://rm_description/meshes/ECO63/Link3.STL" />
      </geometry>
    </collision>
  </link>
  <joint
    name="joint3"
    type="revolute">
    <origin
      xyz="0.41 0 0"
      rpy="0 0 0" />
    <parent
      link="Link2" />
    <child
      link="Link3" />
    <axis
      xyz="0 0 1" />
    <limit
      lower="-2.95"
      upper="2.76"
      effort="100"
      velocity="1" />
    <dynamics
      damping="50"
      friction="1" />
  </joint>
  <link
    name="Link4">
    <inertial>
      <origin
        xyz="6.6185E-07 -0.0098798 0.013446"
        rpy="0 0 0" />
      <mass
        value="0.27261" />
      <inertia
        ixx="0.00023835"
        ixy="2.6006E-09"
        ixz="-2.5717E-09"
        iyy="0.00019072"
        iyz="-4.0013E-05"
        izz="0.0001713" />
    </inertial>
    <visual>
      <origin
        xyz="0 0 0"
        rpy="0 0 0" />
      <geometry>
        <mesh
          filename="package://rm_description/meshes/ECO63/Link4.STL" />
      </geometry>
      <material
        name="">
        <color
          rgba="0.79216 0.81961 0.93333 1" />
      </material>
    </visual>
    <collision>
      <origin
        xyz="0 0 0"
        rpy="0 0 0" />
      <geometry>
        <mesh
          filename="package://rm_description/meshes/ECO63/Link4.STL" />
      </geometry>
    </collision>
  </link>
  <joint
    name="joint4"
    type="revolute">
    <origin
      xyz="0.38 0 -0.0589"
      rpy="0 0 1.5708" />
    <parent
      link="Link3" />
    <child
      link="Link4" />
    <axis
      xyz="0 0 1" />
    <limit
      lower="-2.44"
      upper="2.44"
      effort="100"
      velocity="1" />
    <dynamics
      damping="50"
      friction="1" />
  </joint>
  <link
    name="Link5">
    <inertial>
      <origin
        xyz="-3.0395E-07 7.9935E-05 -0.014767"
        rpy="0 0 0" />
      <mass
        value="0.31149" />
      <inertia
        ixx="0.00030885"
        ixy="-5.8024E-09"
        ixz="3.5085E-09"
        iyy="0.00024407"
        iyz="-2.2834E-06"
        izz="0.0002027" />
    </inertial>
    <visual>
      <origin
        xyz="0 0 0"
        rpy="0 0 0" />
      <geometry>
        <mesh
          filename="package://rm_description/meshes/ECO63/Link5.STL" />
      </geometry>
      <material
        name="">
        <color
          rgba="0.86667 0.86667 0.8902 1" />
      </material>
    </visual>
    <collision>
      <origin
        xyz="0 0 0"
        rpy="0 0 0" />
      <geometry>
        <mesh
          filename="package://rm_description/meshes/ECO63/Link5.STL" />
      </geometry>
    </collision>
  </link>
  <joint
    name="joint5"
    type="revolute">
    <origin
      xyz="0 -0.11 0"
      rpy="1.5708 0 0" />
    <parent
      link="Link4" />
    <child
      link="Link5" />
    <axis
      xyz="0 0 1" />
    <limit
      lower="-3.14"
      upper="3.14"
      effort="100"
      velocity="1" />
    <dynamics
      damping="50"
      friction="1" />
  </joint>
  <link
    name="Link6">
    <inertial>
      <origin
        xyz="0.00065547 -0.00036962 -0.015297"
        rpy="0 0 0" />
      <mass
        value="0.080797" />
      <inertia
        ixx="0"
        ixy="0"
        ixz="0"
        iyy="0"
        iyz="0"
        izz="0" />
    </inertial>
    <visual>
      <origin
        xyz="0 0 0"
        rpy="0 0 0" />
      <geometry>
        <mesh
          filename="package://rm_description/meshes/ECO63/Link6.STL" />
      </geometry>
      <material
        name="">
        <color
          rgba="0.79216 0.81961 0.93333 1" />
      </material>
    </visual>
    <collision>
      <origin
        xyz="0 0 0"
        rpy="0 0 0" />
      <geometry>
        <mesh
          filename="package://rm_description/meshes/ECO63/Link6.STL" />
      </geometry>
    </collision>
  </link>
  <joint
    name="joint6"
    type="revolute">
    <origin
      xyz="0 0.079501 0"
      rpy="-1.5708 0 0" />
    <parent
      link="Link5" />
    <child
      link="Link6" />
    <axis
      xyz="0 0 1" />
    <limit
      lower="-6.28"
      upper="6.28"
      effort="100"
      velocity="1" />
    <dynamics
      damping="50"
      friction="1" />
  </joint>
    <!-- Transmissions for ROS Control -->
  <xacro:macro name="transmission_block" params="joint_name">
    <transmission name="tran1">
      <type>transmission_interface/SimpleTransmission</type>
      <joint name="${joint_name}">
        <hardwareInterface>hardware_interface/PositionJointInterface</hardwareInterface>
      </joint>
      <actuator name="motor1">
        <hardwareInterface>hardware_interface/PositionJointInterface</hardwareInterface>
        <mechanicalReduction>1</mechanicalReduction>
      </actuator>
    </transmission>
  </xacro:macro>
    
  <xacro:transmission_block joint_name="joint1"/>
  <xacro:transmission_block joint_name="joint2"/>
  <xacro:transmission_block joint_name="joint3"/>
  <xacro:transmission_block joint_name="joint4"/>
  <xacro:transmission_block joint_name="joint5"/>
  <xacro:transmission_block joint_name="joint6"/>

  <!-- ros_control plugin -->
  <gazebo>
    <plugin name="gazebo_ros_control" filename="libgazebo_ros_control.so">
      <robotNamespace>/arm</robotNamespace>
      <robotSimType>gazebo_ros_control/DefaultRobotHWSim</robotSimType>
      <legacyModeNS>true</legacyModeNS>
    </plugin>
  </gazebo>
</robot>